<?xml version="1.0" ?>
<!-- =================================================================================== -->
<!-- |    This document was autogenerated by xacro from mybot.xacro                    | -->
<!-- |    EDITING THIS FILE BY HAND IS NOT RECOMMENDED                                 | -->
<!-- =================================================================================== -->
<robot name="myrobot" xmlns:xacro="http://www.ros.org/wiki/xacro">
  <!-- <static>false</static> -->
  <material name="black">
    <color rgba="0.0 0.0 0.0 1.0"/>
  </material>
  <material name="blue">
    <color rgba="0.0 0.0 0.8 1.0"/>
  </material>
  <material name="green">
    <color rgba="0.0 0.8 0.0 1.0"/>
  </material>
  <material name="grey">
    <color rgba="0.2 0.2 0.2 1.0"/>
  </material>
  <material name="orange">
    <color rgba="1.0 0.423529411765 0.0392156862745 1.0"/>
  </material>
  <material name="brown">
    <color rgba="0.870588235294 0.811764705882 0.764705882353 1.0"/>
  </material>
  <material name="red">
    <color rgba="0.8 0.0 0.0 1.0"/>
  </material>
  <material name="white">
    <color rgba="1.0 1.0 1.0 1.0"/>
  </material>
  <gazebo>
    <plugin filename="libgazebo_ros_control.so" name="gazebo_ros_control">
      <robotNamespace>/mybot</robotNamespace>
      <alwaysOn>true</alwaysOn>
      <updateRate>0.0</updateRate>
      <robotSimType>gazebo_ros_control/DefaultRobotHWSim</robotSimType>
    </plugin>
  </gazebo>
  <!-- <gazebo reference="torso">
      <material>Gazebo/Blue</material>
    </gazebo>
  <gazebo reference="base">
      <material>Gazebo/Red</material>
    </gazebo>
    <gazebo reference="hips">
        <material>Gazebo/Red</material>
      </gazebo>
  <gazebo reference="right_leg">
      <material>Gazebo/Blue</material>
    </gazebo>
    <gazebo reference="right_knee">
        <material>Gazebo/Blue</material>
      </gazebo>
  <gazebo reference="right_hip_fixed">
      <material>Gazebo/Blue</material>
    </gazebo>
  <gazebo reference="right_hip">
      <material>Gazebo/Blue</material>
    </gazebo>
  <gazebo reference="right_knee_joint">
      <material>Gazebo/Blue</material>
    </gazebo>
  <gazebo reference="right_lower_leg">
      <material>Gazebo/Red</material>
    </gazebo>
  <gazebo reference="right_ankle">
      <material>Gazebo/Red</material>
    </gazebo>
  <gazebo reference="right_foot">
        <material>Gazebo/Red</material>
      </gazebo>
  <gazebo reference="right_toe_joint">
      <material>Gazebo/Red</material>
    </gazebo>
  <gazebo reference="right_toe_joiner">
      <material>Gazebo/Red</material>
    </gazebo>
  <gazebo reference="right_toe">
      <material>Gazebo/Red</material>
    </gazebo>
  <gazebo reference="left_leg">
      <material>Gazebo/Blue</material>
    </gazebo>
    <gazebo reference="left_knee">
        <material>Gazebo/Blue</material>
      </gazebo>
  <gazebo reference="left_hip_fixed">
      <material>Gazebo/Blue</material>
    </gazebo>
  <gazebo reference="left_hip">
      <material>Gazebo/Blue</material>
    </gazebo>
  <gazebo reference="left_knee_joint">
      <material>Gazebo/Blue</material>
    </gazebo>
  <gazebo reference="left_lower_leg">
      <material>Gazebo/Red</material>
    </gazebo>
  <gazebo reference="left_ankle">
      <material>Gazebo/Red</material>
    </gazebo>
  <gazebo reference="left_foot">
        <material>Gazebo/Red</material>
      </gazebo>
  <gazebo reference="left_toe_joint">
      <material>Gazebo/Red</material>
    </gazebo>
  <gazebo reference="left_toe_joiner">
      <material>Gazebo/Red</material>
    </gazebo>
  <gazebo reference="left_toe">
      <material>Gazebo/Red</material>
    </gazebo>
  <gazebo reference="camera_link">
      <mu1>0.2</mu1>
      <mu2>0.2</mu2>
      <material>Gazebo/Red</material>
    </gazebo> -->
  <gazebo reference="left_foot">
    <mu1>9000</mu1>
    <mu2>9000</mu2>
    <kp>1000000.0</kp>
    <kd>10.0</kd>
    <minDepth>0.001</minDepth>
    <maxContacts>1</maxContacts>
  </gazebo>
  <gazebo reference="right_foot">
    <mu1>9000</mu1>
    <mu2>9000</mu2>
    <kp>1000000.0</kp>
    <kd>10.0</kd>
    <minDepth>0.001</minDepth>
    <maxContacts>1</maxContacts>
  </gazebo>
  <gazebo reference="base">
    <material>Gazebo/Orange</material>
  </gazebo>
  <gazebo reference="hips">
    <material>Gazebo/Orange</material>
  </gazebo>
  <gazebo reference="camera_link">
    <mu1>0.2</mu1>
    <mu2>0.2</mu2>
    <material>Gazebo/Green</material>
  </gazebo>
  <gazebo reference="camera_link">
    <sensor name="camera1" type="camera">
      <update_rate>30.0</update_rate>
      <camera name="head">
        <horizontal_fov>1.3962634</horizontal_fov>
        <image>
          <width>800</width>
          <height>800</height>
          <format>R8G8B8</format>
        </image>
        <clip>
          <near>0.02</near>
          <far>300</far>
        </clip>
        <noise>
          <type>gaussian</type>
          <!-- Noise is sampled independently per pixel on each frame.
                 That pixel's noise value is added to each of its color
                 channels, which at that point lie in the range [0,1]. -->
          <mean>0.0</mean>
          <stddev>0.007</stddev>
        </noise>
      </camera>
      <plugin filename="libgazebo_ros_camera.so" name="camera_controller">
        <alwaysOn>true</alwaysOn>
        <updateRate>0.0</updateRate>
        <cameraName>mybot/camera1</cameraName>
        <imageTopicName>image_raw</imageTopicName>
        <cameraInfoTopicName>camera_info</cameraInfoTopicName>
        <frameName>camera_link_optical</frameName>
        <!-- setting hackBaseline to anything but 0.0 will cause a misalignment
              between the gazebo sensor image and the frame it is supposed to
              be attached to -->
        <hackBaseline>0.0</hackBaseline>
        <distortionK1>0.0</distortionK1>
        <distortionK2>0.0</distortionK2>
        <distortionK3>0.0</distortionK3>
        <distortionT1>0.0</distortionT1>
        <distortionT2>0.0</distortionT2>
        <CxPrime>0</CxPrime>
        <Cx>0.0</Cx>
        <Cy>0.0</Cy>
        <focalLength>0.0</focalLength>
      </plugin>
    </sensor>
  </gazebo>
  <!--macro name="cylinder_inertia" params="m r h">
    <inertia  ixx="${m*(3*r*r+h*h)/12}" ixy = "0" ixz = "0"
      iyy="${m*(3*r*r+h*h)/12}" iyz = "0"
      izz="${m*r*r/2}"
    />
  </macro>

  <macro name="box_inertia" params="m x y z">
    <inertia  ixx="${m*(y*y+z*z)/12}" ixy = "0" ixz = "0"
      iyy="${m*(x*x+z*z)/12}" iyz = "0"
      izz="${m*(x*x+z*z)/12}"
    />
  </macro>

  <macro name="sphere_inertia" params="m r">
    <inertia  ixx="${2*m*r*r/5}" ixy = "0" ixz = "0"
      iyy="${2*m*r*r/5}" iyz = "0"
      izz="${2*m*r*r/5}"
    />
  </macro>







  <macro name="wheel" params="lr tY">

    <link name="${lr}_wheel">
      <collision>
        <origin xyz="0 0 0" rpy="0 ${PI/2} ${PI/2}" />
        <geometry>
          <cylinder length="${wheelWidth}" radius="${wheelRadius}"/>
        </geometry>
      </collision>

      <visual>
        <origin xyz="0 0 0" rpy="0 ${PI/2} ${PI/2}" />
        <geometry>
          <cylinder length="${wheelWidth}" radius="${wheelRadius}"/>
        </geometry>
        <material name="black"/>
      </visual>

      <inertial>
        <origin xyz="0 0 0" rpy="0 ${PI/2} ${PI/2}" />
        <mass value="${wheelMass}"/>
        <cylinder_inertia m="${wheelMass}" r="${wheelRadius}" h="${wheelWidth}"/>
      </inertial>
    </link>

    <gazebo reference="${lr}_wheel">
      <mu1 value="1.0"/>
      <mu2 value="1.0"/>
      <kp  value="10000000.0" />
      <kd  value="1.0" />
      <fdir1 value="1 0 0"/>
      <material>Gazebo/Black</material>
    </gazebo>


    <joint name="${lr}_wheel_hinge" type="continuous">
      <parent link="chassis"/>
      <child link="${lr}_wheel"/>
    <origin xyz="${-wheelPos+chassisLength/2} ${tY*wheelWidth/2+tY*chassisWidth/2} ${wheelRadius}" rpy="0 0 0" />
      <axis xyz="0 1 0" rpy="0 0 0" />
      <limit effort="10000" velocity="10000"/>
      <joint_properties damping="0.0" friction="0.0"/>
    </joint>


    <transmission name="${lr}_trans">
      <type>transmission_interface/SimpleTransmission</type>
      <joint name="${lr}_wheel_hinge">
        <hardwareInterface>EffortJointInterface</hardwareInterface>
      </joint>
      <actuator name="${lr}Motor">
        <hardwareInterface>EffortJointInterface</hardwareInterface>
        <mechanicalReduction>10</mechanicalReduction>
      </actuator>
    </transmission>

  </macro-->
  <!-- Size of square "camera" box -->
  <link name="base">
    <pose>0 0 0 0 0 0</pose>
    <inertial>
      <mass value="0.01"/>
      <origin rpy=" 0 0 0" xyz="0 0 0"/>
      <inertia ixx="0.4" ixy="0.0" ixz="0.0" iyy="0.4" iyz="0.0" izz="0.2"/>
    </inertial>
    <collision name="collision">
      <geometry>
        <box size="0.18 0.4 0.1"/>
      </geometry>
    </collision>
    <visual name="base_visual">
      <origin rpy=" 0 0 0" xyz="0 0 0"/>
      <geometry>
        <box size="0.18 0.4 0.1"/>
      </geometry>
    </visual>
  </link>
  <link name="hips">
    <pose>0 0 0 0 0 0</pose>
    <inertial>
      <mass value="10"/>
      <origin rpy=" 0 0 0" xyz="0 0 0"/>
      <inertia ixx="0.4" ixy="0.0" ixz="0.0" iyy="0.4" iyz="0.0" izz="0.2"/>
    </inertial>
    <collision name="collision">
      <geometry>
        <box size="0.18 0.4 0.1"/>
      </geometry>
    </collision>
    <visual name="hips_visual">
      <material name="orange"/>
      <origin rpy=" 0 0 0" xyz="0 0 0"/>
      <geometry>
        <box size="0.18 0.4 0.1"/>
      </geometry>
    </visual>
  </link>
  <link name="torso">
    <inertial>
      <mass value="20"/>
      <origin rpy=" 0 0 0" xyz="0 0 0"/>
      <inertia ixx="0.4" ixy="0.0" ixz="0.0" iyy="0.4" iyz="0.0" izz="0.2"/>
    </inertial>
    <collision name="collision">
      <geometry>
        <box size="0.15 0.3 0.6"/>
      </geometry>
    </collision>
    <visual name="torso_visual">
      <origin rpy=" 0 0 0" xyz="0 0 0"/>
      <geometry>
        <box size="0.15 0.3 0.6"/>
      </geometry>
    </visual>
  </link>
  <joint name="base_fixed" type="fixed">
    <origin rpy="0 0 0" xyz="0 0 0"/>
    <child link="hips"/>
    <parent link="base"/>
    <axis rpy="0 0 0" xyz="0 0 0"/>
  </joint>
  <joint name="torso_fixed" type="fixed">
    <origin rpy="0 0 0" xyz="0 0 0.3"/>
    <child link="torso"/>
    <parent link="hips"/>
    <axis rpy="0 0 0" xyz="0 0 0"/>
  </joint>
  <!-- =============================================================================== -->
  <!-- <link name="shoulders">
    <inertial>
      <mass value="${shoulders_mass}"/>
      <origin xyz="0 0 0" rpy=" 0 0 0"/>
      <inertia
        ixx="0.5" ixy="0" ixz="0"
        iyy="1.0" iyz="0"
        izz="0.1"
      />
    </inertial>
    <collision name="collision">
      <geometry>
        <box size="${shoulders_x} ${shoulders_y} ${shoulders_z}"/>
      </geometry>
    </collision>
    <visual name="shoulders_visual">
      <material name="orange"/>
      <origin xyz="0 0 0" rpy=" 0 0 0"/>
      <geometry>
        <box size="${shoulders_x} ${shoulders_y} ${shoulders_z}"/>
      </geometry>
    </visual>
  </link>

  <joint type="fixed" name="shoulders_fixed">
    <origin xyz="0 0 0.3" rpy="0 0 0"/>
    <child link="shoulders"/>
    <parent link="torso"/>
    <axis xyz="0 0 0" rpy="0 0 0"/>
  </joint>

  <link name="left_upper_arm">
    <inertial>
      <mass value="${upper_arm_mass}"/>
      <origin xyz="0 0 0" rpy=" 0 0 0"/>
      <inertia
        ixx="0.5" ixy="0" ixz="0"
        iyy="1.0" iyz="0"
        izz="0.1"
      />
    </inertial>
    <collision name="left_collision">
      <geometry>
        <box size="${upper_arm_x} ${upper_arm_y} ${upper_arm_z}"/>
      </geometry>
    </collision>
    <visual name="left_upper_arm_visual">
      <origin xyz="0 0 0" rpy=" 0 0 0"/>
      <geometry>
        <box size="${upper_arm_x} ${upper_arm_y} ${upper_arm_z}"/>
      </geometry>
    </visual>
  </link>

  <link name="left_forearm">
    <inertial>
      <mass value="${forearm_mass}"/>
      <origin xyz="0 0 0" rpy=" 0 0 0"/>
      <inertia
        ixx="0.5" ixy="0" ixz="0"
        iyy="1.0" iyz="0"
        izz="0.1"
      />
    </inertial>
    <collision name="left_forearm_collision">
      <geometry>
        <box size="${forearm_x} ${forearm_y} ${forearm_z}"/>
      </geometry>
    </collision>
    <visual name="left_forearm_visual">
      <origin xyz="0 0 0" rpy=" 0 0 0"/>
      <geometry>
        <box size="${forearm_x} ${forearm_y} ${forearm_z}"/>
      </geometry>
    </visual>
  </link>

  <link name="left_shoulder_z">
    <collision name="left_shoulder_x_collision">
      <origin xyz="0 0 0" rpy="0 1.5708 0"/>
      <geometry>
        <cylinder radius="${joint_radius}" length="${joint_length}"/>
      </geometry>
    </collision>
    <visual name="left_shoulder_x_visual">
      <origin xyz="0 0 0" rpy="0 1.5708 0"/>
      <geometry>
        <cylinder radius="${joint_radius}" length="${joint_length}"/>
      </geometry>
    </visual>
    <inertial>
      <origin xyz="0 0 0" rpy="0 0 0" />
      <mass value="0.05" />
      <inertia
        ixx="1.0" ixy="0.0" ixz="0.0"
        iyy="1.0" iyz="0.0"
        izz="1.0" />
    </inertial>
  </link>

  <joint type="fixed" name="left_upper_arm_fixed">
    <origin xyz="0 0 -0.3" rpy="0 0 0"/>
    <child link="left_upper_arm"/>
    <parent link="left_shoulder_z"/>
    <axis xyz="0 0 0" rpy="0 0 0"/>
  </joint>

  <joint type="revolute" name="left_shoulder_z_joint">
    <origin xyz="0 0.20 -0.07" rpy="0 0 0"/>
    <child link="left_shoulder_z"/>
    <parent link="shoulders"/>
    <axis xyz="0 0 1" rpy="0 0 0"/>
    <limit effort="100" velocity="100" lower="${hip_z_min}" upper="${hip_z_max}"/>
    <joint_properties damping="0.5" friction="0.5"/>
  </joint> -->
  <!-- =================================================================================== -->
  <!--  LEGS -->
  <!--  LEFT-->
  <link name="left_hip_x">
    <collision name="left_hip_x_collision">
      <origin rpy="0 1.5708 0" xyz="0 0 0"/>
      <geometry>
        <cylinder length="0.12" radius="0.04"/>
      </geometry>
    </collision>
    <visual name="left_hip_x_visual">
      <origin rpy="0 1.5708 0" xyz="0 0 0"/>
      <geometry>
        <cylinder length="0.12" radius="0.04"/>
      </geometry>
    </visual>
    <inertial>
      <origin rpy="0 0 0" xyz="0 0 0"/>
      <mass value="0.05"/>
      <inertia ixx="0.4" ixy="0.0" ixz="0.0" iyy="0.4" iyz="0.0" izz="0.2"/>
    </inertial>
  </link>
  <link name="left_hip_y">
    <collision name="left_hip_y_collision">
      <origin rpy="1.5708 0 0" xyz="0 0 0"/>
      <geometry>
        <cylinder length="0.12" radius="0.04"/>
      </geometry>
    </collision>
    <visual name="left_hip_y_visual">
      <origin rpy="1.5708 0 0" xyz="0 0 0"/>
      <geometry>
        <cylinder length="0.12" radius="0.04"/>
      </geometry>
    </visual>
    <inertial>
      <origin rpy="0 0 0" xyz="0 0 0"/>
      <mass value="0.05"/>
      <inertia ixx="0.4" ixy="0.0" ixz="0.0" iyy="0.4" iyz="0.0" izz="0.2"/>
    </inertial>
  </link>
  <link name="left_hip_z">
    <collision name="left_hip_z_collision">
      <origin rpy="0 0 0" xyz="0 0 0"/>
      <geometry>
        <cylinder length="0.12" radius="0.04"/>
      </geometry>
    </collision>
    <visual name="left_hip_z_visual">
      <origin rpy="0 0 0" xyz="0 0 0"/>
      <geometry>
        <cylinder length="0.12" radius="0.04"/>
      </geometry>
    </visual>
    <inertial>
      <origin rpy="0 0 0" xyz="0 0 0"/>
      <mass value="0.05"/>
      <inertia ixx="0.4" ixy="0.0" ixz="0.0" iyy="0.4" iyz="0.0" izz="0.2"/>
    </inertial>
  </link>
  <joint name="left_hip_z_joint" type="revolute">
    <origin rpy="0 0 0" xyz="0 0.13 -0.07"/>
    <child link="left_hip_z"/>
    <parent link="hips"/>
    <axis rpy="0 0 0" xyz="0 0 1"/>
    <limit effort="100" lower="-0.785" upper="0.785" velocity="100"/>
    <joint_properties damping="0.5" friction="0.5"/>
  </joint>
  <joint name="left_hip_x_joint" type="revolute">
    <origin rpy="0 0 0" xyz="0 0 0"/>
    <child link="left_hip_x"/>
    <parent link="left_hip_z"/>
    <axis rpy="0 0 0" xyz="1 0 0"/>
    <limit effort="100" lower="-0.785" upper="0.785" velocity="100"/>
    <joint_properties damping="0.5" friction="0.5"/>
  </joint>
  <joint name="left_hip_y_joint" type="revolute">
    <origin rpy="0 0 0" xyz="0 0 0"/>
    <child link="left_hip_y"/>
    <parent link="left_hip_x"/>
    <axis rpy="0 0 0" xyz="0 -1 0"/>
    <limit effort="100" lower="-0.785" upper="1.5708" velocity="100"/>
    <joint_properties damping="0.5" friction="0.5"/>
  </joint>
  <transmission name="tran_left_hip_z">
    <type>transmission_interface/SimpleTransmission</type>
    <joint name="left_hip_z_joint">
      <hardwareInterface>hardware_interface/EffortJointInterface</hardwareInterface>
    </joint>
    <actuator name="motor_left_hip_z">
      <hardwareInterface>hardware_interface/EffortJointInterface</hardwareInterface>
      <mechanicalReduction>1</mechanicalReduction>
    </actuator>
  </transmission>
  <transmission name="tran_left_hip_x">
    <type>transmission_interface/SimpleTransmission</type>
    <joint name="left_hip_x_joint">
      <hardwareInterface>hardware_interface/EffortJointInterface</hardwareInterface>
    </joint>
    <actuator name="motor_left_hip_x">
      <hardwareInterface>hardware_interface/EffortJointInterface</hardwareInterface>
      <mechanicalReduction>1</mechanicalReduction>
    </actuator>
  </transmission>
  <transmission name="tran_left_hip_y">
    <type>transmission_interface/SimpleTransmission</type>
    <joint name="left_hip_y_joint">
      <hardwareInterface>hardware_interface/EffortJointInterface</hardwareInterface>
    </joint>
    <actuator name="motor_left_hip_y">
      <hardwareInterface>hardware_interface/EffortJointInterface</hardwareInterface>
      <mechanicalReduction>1</mechanicalReduction>
    </actuator>
  </transmission>
  <link name="left_leg">
    <inertial>
      <mass value="5"/>
      <origin rpy=" 0 0 0" xyz="0 0 0"/>
      <inertia ixx="0.4" ixy="0.0" ixz="0.0" iyy="0.4" iyz="0.0" izz="0.2"/>
    </inertial>
    <collision name="collision">
      <geometry>
        <box size="0.08 0.12 0.4"/>
      </geometry>
    </collision>
    <visual name="left_leg_visual">
      <origin rpy=" 0 0 0" xyz="0 0 0"/>
      <geometry>
        <box size="0.08 0.12 0.4"/>
      </geometry>
    </visual>
  </link>
  <joint name="left_hip_fixed" type="fixed">
    <origin rpy="0 0 3.14159265359" xyz="0 0 -0.2"/>
    <child link="left_leg"/>
    <parent link="left_hip_y"/>
    <axis rpy="0 0 0" xyz="0 0 0"/>
  </joint>
  <link name="left_knee">
    <collision name="left_knee_collision">
      <origin rpy="1.5708 0 3.14159265359" xyz="0 0 0"/>
      <geometry>
        <cylinder length="0.12" radius="0.04"/>
      </geometry>
    </collision>
    <visual name="left_knee_visual">
      <origin rpy="1.5708 0 0" xyz="0 0 0"/>
      <geometry>
        <cylinder length="0.12" radius="0.04"/>
      </geometry>
    </visual>
    <inertial>
      <origin rpy="1.5708 0 0" xyz="0 0 0"/>
      <mass value="0"/>
      <inertia ixx="0.4" ixy="0.0" ixz="0.0" iyy="0.4" iyz="0.0" izz="0.2"/>
    </inertial>
  </link>
  <link name="left_lower_leg">
    <inertial>
      <mass value="5"/>
      <origin rpy=" 0 0 0" xyz="0 0 0"/>
      <inertia ixx="0.4" ixy="0.0" ixz="0.0" iyy="0.4" iyz="0.0" izz="0.2"/>
    </inertial>
    <collision name="left_lower_leg_collision">
      <geometry>
        <box size="0.08 0.12 0.4"/>
      </geometry>
    </collision>
    <visual name="left_lower_leg_visual">
      <origin rpy=" 0 0 0" xyz="0 0 0"/>
      <geometry>
        <box size="0.08 0.12 0.4"/>
      </geometry>
    </visual>
  </link>
  <joint name="left_knee_joint" type="revolute">
    <origin rpy="0 0 0" xyz="0.0 0 -0.2"/>
    <child link="left_knee"/>
    <parent link="left_leg"/>
    <axis rpy="0 0 0" xyz="0 1 0"/>
    <limit effort="100" lower="-1.5708" upper="0.0" velocity="100"/>
    <joint_properties damping="0.5" friction="0.5"/>
  </joint>
  <joint name="left_knee_fixed" type="fixed">
    <origin rpy="0 0 0" xyz="0 0 -0.2"/>
    <child link="left_lower_leg"/>
    <parent link="left_knee"/>
    <axis rpy="0 0 0" xyz="0 0 0"/>
  </joint>
  <transmission name="tran_left_knee">
    <type>transmission_interface/SimpleTransmission</type>
    <joint name="left_knee_joint">
      <hardwareInterface>hardware_interface/EffortJointInterface</hardwareInterface>
    </joint>
    <actuator name="motor_left_knee">
      <hardwareInterface>hardware_interface/EffortJointInterface</hardwareInterface>
      <mechanicalReduction>1</mechanicalReduction>
    </actuator>
  </transmission>
  <link name="left_ankle_x">
    <collision name="left_ankle_x_collision">
      <origin rpy="0 1.5708 0" xyz="0 0 0"/>
      <geometry>
        <cylinder length="0.12" radius="0.04"/>
      </geometry>
    </collision>
    <visual name="left_ankle_x_visual">
      <origin rpy="0 1.5708 0" xyz="0 0 0"/>
      <geometry>
        <cylinder length="0.12" radius="0.04"/>
      </geometry>
    </visual>
    <inertial>
      <origin rpy="0 1.5708 0" xyz="0 0 0"/>
      <mass value="0.05"/>
      <inertia ixx="0.4" ixy="0.0" ixz="0.0" iyy="0.4" iyz="0.0" izz="0.2"/>
    </inertial>
  </link>
  <link name="left_ankle_y">
    <collision name="left_ankle_y_collision">
      <origin rpy="1.5708 0 0" xyz="0 0 0"/>
      <geometry>
        <cylinder length="0.12" radius="0.04"/>
      </geometry>
    </collision>
    <visual name="left_ankle_y_visual">
      <origin rpy="1.5708 0 0" xyz="0 0 0"/>
      <geometry>
        <cylinder length="0.12" radius="0.04"/>
      </geometry>
    </visual>
    <inertial>
      <origin rpy="1.5708 0 0" xyz="0 0 0"/>
      <mass value="0.05"/>
      <inertia ixx="0.4" ixy="0.0" ixz="0.0" iyy="0.4" iyz="0.0" izz="0.2"/>
    </inertial>
  </link>
  <link name="left_foot">
    <inertial>
      <mass value="1.0"/>
      <origin rpy=" 0 0 0" xyz="0 0 0"/>
      <inertia ixx="0.4" ixy="0.0" ixz="0.0" iyy="0.4" iyz="0.0" izz="0.2"/>
    </inertial>
    <collision name="left_foot_collision">
      <geometry>
        <box size="0.25 0.12 0.05"/>
      </geometry>
    </collision>
    <visual name="left_foot_visual">
      <origin rpy=" 0 0 0" xyz="0 0 0"/>
      <geometry>
        <box size="0.25 0.12 0.05"/>
      </geometry>
    </visual>
  </link>
  <joint name="left_ankle_x_joint" type="revolute">
    <origin rpy="0 0 0" xyz="0.0 0 -0.2"/>
    <child link="left_ankle_x"/>
    <parent link="left_lower_leg"/>
    <axis rpy="0 0 0" xyz="1 0 0"/>
    <limit effort="100" lower="-0.785" upper="0.785" velocity="100"/>
    <joint_properties damping="0.5" friction="0.5"/>
  </joint>
  <joint name="left_ankle_y_joint" type="revolute">
    <origin rpy="0 0 0" xyz="0.0 0 0"/>
    <child link="left_ankle_y"/>
    <parent link="left_ankle_x"/>
    <axis rpy="0 0 0" xyz="0 1 0"/>
    <limit effort="100" lower="-0.785" upper="1.0472" velocity="100"/>
    <joint_properties damping="0.5" friction="0.5"/>
  </joint>
  <joint name="left_ankle_fixed" type="fixed">
    <origin rpy="0 0 0" xyz="-0.03 0 -0.05"/>
    <child link="left_foot"/>
    <parent link="left_ankle_y"/>
    <axis rpy="0 0 0" xyz="1 0 0"/>
  </joint>
  <link name="left_foot_s1">
    <inertial>
      <mass value="0.001"/>
      <origin rpy=" 0 0 0" xyz="0 0 0"/>
      <inertia ixx="0.4" ixy="0.0" ixz="0.0" iyy="0.4" iyz="0.0" izz="0.2"/>
    </inertial>
    <collision name="left_foot_s1_collision">
      <geometry>
        <box size="0.04 0.04 0.002"/>
      </geometry>
    </collision>
    <visual name="left_foot_s1_visual">
      <origin rpy=" 0 0 0" xyz="0 0 0"/>
      <geometry>
        <box size="0.04 0.04 0.002"/>
      </geometry>
    </visual>
  </link>
  <joint name="left_foot_s1_fixed" type="fixed">
    <origin rpy="0 0 0" xyz="0.105 0.04 -0.027"/>
    <child link="left_foot_s1"/>
    <parent link="left_foot"/>
    <axis rpy="0 0 0" xyz="1 0 0"/>
  </joint>
  <link name="left_foot_s2">
    <inertial>
      <mass value="0.001"/>
      <origin rpy=" 0 0 0" xyz="0 0 0"/>
      <inertia ixx="0.4" ixy="0.0" ixz="0.0" iyy="0.4" iyz="0.0" izz="0.2"/>
    </inertial>
    <collision name="left_foot_s2_collision">
      <geometry>
        <box size="0.04 0.04 0.002"/>
      </geometry>
    </collision>
    <visual name="left_foot_s2_visual">
      <origin rpy=" 0 0 0" xyz="0 0 0"/>
      <geometry>
        <box size="0.04 0.04 0.002"/>
      </geometry>
    </visual>
  </link>
  <joint name="left_foot_s2_fixed" type="fixed">
    <origin rpy="0 0 0" xyz="0.105 -0.04 -0.027"/>
    <child link="left_foot_s2"/>
    <parent link="left_foot"/>
    <axis rpy="0 0 0" xyz="1 0 0"/>
  </joint>
  <link name="left_foot_s3">
    <inertial>
      <mass value="0.001"/>
      <origin rpy=" 0 0 0" xyz="0 0 0"/>
      <inertia ixx="0.4" ixy="0.0" ixz="0.0" iyy="0.4" iyz="0.0" izz="0.2"/>
    </inertial>
    <collision name="left_foot_s3_collision">
      <geometry>
        <box size="0.04 0.04 0.002"/>
      </geometry>
    </collision>
    <visual name="left_foot_s3_visual">
      <origin rpy=" 0 0 0" xyz="0 0 0"/>
      <geometry>
        <box size="0.04 0.04 0.002"/>
      </geometry>
    </visual>
  </link>
  <joint name="left_foot_s3_fixed" type="fixed">
    <origin rpy="0 0 0" xyz="-0.105 0.04 -0.027"/>
    <child link="left_foot_s3"/>
    <parent link="left_foot"/>
    <axis rpy="0 0 0" xyz="1 0 0"/>
  </joint>
  <link name="left_foot_s4">
    <inertial>
      <mass value="0.001"/>
      <origin rpy=" 0 0 0" xyz="0 0 0"/>
      <inertia ixx="0.4" ixy="0.0" ixz="0.0" iyy="0.4" iyz="0.0" izz="0.2"/>
    </inertial>
    <collision name="left_foot_s4_collision">
      <geometry>
        <box size="0.04 0.04 0.002"/>
      </geometry>
    </collision>
    <visual name="left_foot_s4_visual">
      <origin rpy=" 0 0 0" xyz="0 0 0"/>
      <geometry>
        <box size="0.04 0.04 0.002"/>
      </geometry>
    </visual>
  </link>
  <joint name="left_foot_s4_fixed" type="fixed">
    <origin rpy="0 0 0" xyz="-0.105 -0.04 -0.027"/>
    <child link="left_foot_s4"/>
    <parent link="left_foot"/>
    <axis rpy="0 0 0" xyz="1 0 0"/>
  </joint>
  <transmission name="tran_left_ankle_x">
    <type>transmission_interface/SimpleTransmission</type>
    <joint name="left_ankle_x_joint">
      <hardwareInterface>hardware_interface/EffortJointInterface</hardwareInterface>
    </joint>
    <actuator name="motor_left_ankle_x">
      <hardwareInterface>hardware_interface/EffortJointInterface</hardwareInterface>
      <mechanicalReduction>1</mechanicalReduction>
    </actuator>
  </transmission>
  <transmission name="tran_left_ankle_y">
    <type>transmission_interface/SimpleTransmission</type>
    <joint name="left_ankle_y_joint">
      <hardwareInterface>hardware_interface/EffortJointInterface</hardwareInterface>
    </joint>
    <actuator name="motor_left_ankle_y">
      <hardwareInterface>hardware_interface/EffortJointInterface</hardwareInterface>
      <mechanicalReduction>1</mechanicalReduction>
    </actuator>
  </transmission>
  <!--  RIGHT LEG-->
  <link name="right_hip_x">
    <collision name="right_hip_x_collision">
      <origin rpy="0 1.5708 0" xyz="0 0 0"/>
      <geometry>
        <cylinder length="0.12" radius="0.04"/>
      </geometry>
    </collision>
    <visual name="right_hip_x_visual">
      <origin rpy="0 1.5708 0" xyz="0 0 0"/>
      <geometry>
        <cylinder length="0.12" radius="0.04"/>
      </geometry>
    </visual>
    <inertial>
      <origin rpy="0 0 0" xyz="0 0 0"/>
      <mass value="0.05"/>
      <inertia ixx="0.4" ixy="0.0" ixz="0.0" iyy="0.4" iyz="0.0" izz="0.2"/>
    </inertial>
  </link>
  <link name="right_hip_y">
    <collision name="right_hip_y_collision">
      <origin rpy="1.5708 0 0" xyz="0 0 0"/>
      <geometry>
        <cylinder length="0.12" radius="0.04"/>
      </geometry>
    </collision>
    <visual name="right_hip_y_visual">
      <origin rpy="1.5708 0 0" xyz="0 0 0"/>
      <geometry>
        <cylinder length="0.12" radius="0.04"/>
      </geometry>
    </visual>
    <inertial>
      <origin rpy="0 0 0" xyz="0 0 0"/>
      <mass value="0.05"/>
      <inertia ixx="0.4" ixy="0.0" ixz="0.0" iyy="0.4" iyz="0.0" izz="0.2"/>
    </inertial>
  </link>
  <link name="right_hip_z">
    <collision name="right_hip_z_collision">
      <origin rpy="0 0 0" xyz="0 0 0"/>
      <geometry>
        <cylinder length="0.12" radius="0.04"/>
      </geometry>
    </collision>
    <visual name="right_hip_z_visual">
      <origin rpy="0 0 0" xyz="0 0 0"/>
      <geometry>
        <cylinder length="0.12" radius="0.04"/>
      </geometry>
    </visual>
    <inertial>
      <origin rpy="0 0 0" xyz="0 0 0"/>
      <mass value="0.05"/>
      <inertia ixx="0.4" ixy="0.0" ixz="0.0" iyy="0.4" iyz="0.0" izz="0.2"/>
    </inertial>
  </link>
  <joint name="right_hip_z_joint" type="revolute">
    <origin rpy="0 0 0" xyz="0 -0.13 -0.07"/>
    <child link="right_hip_z"/>
    <parent link="hips"/>
    <axis rpy="0 0 0" xyz="0 0 1"/>
    <limit effort="100" lower="-0.785" upper="0.785" velocity="100"/>
    <joint_properties damping="0.5" friction="0.5"/>
  </joint>
  <joint name="right_hip_x_joint" type="revolute">
    <origin rpy="0 0 0" xyz="0 0 0"/>
    <child link="right_hip_x"/>
    <parent link="right_hip_z"/>
    <axis rpy="0 0 0" xyz="1 0 0"/>
    <limit effort="100" lower="-0.785" upper="0.785" velocity="100"/>
    <joint_properties damping="0.5" friction="0.5"/>
  </joint>
  <joint name="right_hip_y_joint" type="revolute">
    <origin rpy="0 0 0" xyz="0 0 0"/>
    <child link="right_hip_y"/>
    <parent link="right_hip_x"/>
    <axis rpy="0 0 0" xyz="0 -1 0"/>
    <limit effort="100" lower="-0.785" upper="1.5708" velocity="100"/>
    <joint_properties damping="0.5" friction="0.5"/>
  </joint>
  <transmission name="tran_right_hip_z">
    <type>transmission_interface/SimpleTransmission</type>
    <joint name="right_hip_z_joint">
      <hardwareInterface>hardware_interface/EffortJointInterface</hardwareInterface>
    </joint>
    <actuator name="motor_right_hip_z">
      <hardwareInterface>hardware_interface/EffortJointInterface</hardwareInterface>
      <mechanicalReduction>1</mechanicalReduction>
    </actuator>
  </transmission>
  <transmission name="tran_right_hip_x">
    <type>transmission_interface/SimpleTransmission</type>
    <joint name="right_hip_x_joint">
      <hardwareInterface>hardware_interface/EffortJointInterface</hardwareInterface>
    </joint>
    <actuator name="motor_right_hip_x">
      <hardwareInterface>hardware_interface/EffortJointInterface</hardwareInterface>
      <mechanicalReduction>1</mechanicalReduction>
    </actuator>
  </transmission>
  <transmission name="tran_right_hip_y">
    <type>transmission_interface/SimpleTransmission</type>
    <joint name="right_hip_y_joint">
      <hardwareInterface>hardware_interface/EffortJointInterface</hardwareInterface>
    </joint>
    <actuator name="motor_right_hip_y">
      <hardwareInterface>hardware_interface/EffortJointInterface</hardwareInterface>
      <mechanicalReduction>1</mechanicalReduction>
    </actuator>
  </transmission>
  <link name="right_leg">
    <inertial>
      <mass value="5"/>
      <origin rpy=" 0 0 0" xyz="0 0 0"/>
      <inertia ixx="0.4" ixy="0.0" ixz="0.0" iyy="0.4" iyz="0.0" izz="0.2"/>
    </inertial>
    <collision name="collision">
      <geometry>
        <box size="0.08 0.12 0.4"/>
      </geometry>
    </collision>
    <visual name="right_leg_visual">
      <origin rpy=" 0 0 0" xyz="0 0 0"/>
      <geometry>
        <box size="0.08 0.12 0.4"/>
      </geometry>
    </visual>
  </link>
  <joint name="right_hip_fixed" type="fixed">
    <origin rpy="0 0 3.14159265359" xyz="0 0 -0.2"/>
    <child link="right_leg"/>
    <parent link="right_hip_y"/>
    <axis rpy="0 0 0" xyz="0 0 0"/>
  </joint>
  <link name="right_knee">
    <collision name="right_knee_collision">
      <origin rpy="1.5708 0 3.14159265359" xyz="0 0 0"/>
      <geometry>
        <cylinder length="0.12" radius="0.04"/>
      </geometry>
    </collision>
    <visual name="right_knee_visual">
      <origin rpy="1.5708 0 0" xyz="0 0 0"/>
      <geometry>
        <cylinder length="0.12" radius="0.04"/>
      </geometry>
    </visual>
    <inertial>
      <origin rpy="1.5708 0 0" xyz="0 0 0"/>
      <mass value="0"/>
      <inertia ixx="0.4" ixy="0.0" ixz="0.0" iyy="0.4" iyz="0.0" izz="0.2"/>
    </inertial>
  </link>
  <link name="right_lower_leg">
    <inertial>
      <mass value="5"/>
      <origin rpy=" 0 0 0" xyz="0 0 0"/>
      <inertia ixx="0.4" ixy="0.0" ixz="0.0" iyy="0.4" iyz="0.0" izz="0.2"/>
    </inertial>
    <collision name="right_lower_leg_collision">
      <geometry>
        <box size="0.08 0.12 0.4"/>
      </geometry>
    </collision>
    <visual name="right_lower_leg_visual">
      <origin rpy=" 0 0 0" xyz="0 0 0"/>
      <geometry>
        <box size="0.08 0.12 0.4"/>
      </geometry>
    </visual>
  </link>
  <joint name="right_knee_joint" type="revolute">
    <origin rpy="0 0 0" xyz="0.0 0 -0.2"/>
    <child link="right_knee"/>
    <parent link="right_leg"/>
    <axis rpy="0 0 0" xyz="0 1 0"/>
    <limit effort="100" lower="-1.5708" upper="0.0" velocity="100"/>
    <joint_properties damping="0.5" friction="0.5"/>
  </joint>
  <joint name="right_knee_fixed" type="fixed">
    <origin rpy="0 0 0" xyz="0 0 -0.2"/>
    <child link="right_lower_leg"/>
    <parent link="right_knee"/>
    <axis rpy="0 0 0" xyz="0 0 0"/>
  </joint>
  <transmission name="tran_right_knee">
    <type>transmission_interface/SimpleTransmission</type>
    <joint name="right_knee_joint">
      <hardwareInterface>hardware_interface/EffortJointInterface</hardwareInterface>
    </joint>
    <actuator name="motor_right_knee">
      <hardwareInterface>hardware_interface/EffortJointInterface</hardwareInterface>
      <mechanicalReduction>1</mechanicalReduction>
    </actuator>
  </transmission>
  <link name="right_ankle_x">
    <collision name="right_ankle_x_collision">
      <origin rpy="0 1.5708 0" xyz="0 0 0"/>
      <geometry>
        <cylinder length="0.12" radius="0.04"/>
      </geometry>
    </collision>
    <visual name="right_ankle_x_visual">
      <origin rpy="0 1.5708 0" xyz="0 0 0"/>
      <geometry>
        <cylinder length="0.12" radius="0.04"/>
      </geometry>
    </visual>
    <inertial>
      <origin rpy="0 1.5708 0" xyz="0 0 0"/>
      <mass value="0.05"/>
      <inertia ixx="0.4" ixy="0.0" ixz="0.0" iyy="0.4" iyz="0.0" izz="0.2"/>
    </inertial>
  </link>
  <link name="right_ankle_y">
    <collision name="right_ankle_y_collision">
      <origin rpy="1.5708 0 0" xyz="0 0 0"/>
      <geometry>
        <cylinder length="0.12" radius="0.04"/>
      </geometry>
    </collision>
    <visual name="right_ankle_y_visual">
      <origin rpy="1.5708 0 0" xyz="0 0 0"/>
      <geometry>
        <cylinder length="0.12" radius="0.04"/>
      </geometry>
    </visual>
    <inertial>
      <origin rpy="1.5708 0 0" xyz="0 0 0"/>
      <mass value="0.05"/>
      <inertia ixx="0.4" ixy="0.0" ixz="0.0" iyy="0.4" iyz="0.0" izz="0.2"/>
    </inertial>
  </link>
  <link name="right_foot">
    <inertial>
      <mass value="1.0"/>
      <origin rpy=" 0 0 0" xyz="0 0 0"/>
      <inertia ixx="0.4" ixy="0.0" ixz="0.0" iyy="0.4" iyz="0.0" izz="0.2"/>
    </inertial>
    <collision name="right_foot_collision">
      <geometry>
        <box size="0.25 0.12 0.05"/>
      </geometry>
    </collision>
    <visual name="right_foot_visual">
      <origin rpy=" 0 0 0" xyz="0 0 0"/>
      <geometry>
        <box size="0.25 0.12 0.05"/>
      </geometry>
    </visual>
  </link>
  <joint name="right_ankle_x_joint" type="revolute">
    <origin rpy="0 0 0" xyz="0.0 0 -0.2"/>
    <child link="right_ankle_x"/>
    <parent link="right_lower_leg"/>
    <axis rpy="0 0 0" xyz="1 0 0"/>
    <limit effort="100" lower="-0.785" upper="0.785" velocity="100"/>
    <joint_properties damping="0.5" friction="0.5"/>
  </joint>
  <joint name="right_ankle_y_joint" type="revolute">
    <origin rpy="0 0 0" xyz="0.0 0 0"/>
    <child link="right_ankle_y"/>
    <parent link="right_ankle_x"/>
    <axis rpy="0 0 0" xyz="0 1 0"/>
    <limit effort="100" lower="-0.785" upper="1.0472" velocity="100"/>
    <joint_properties damping="0.5" friction="0.5"/>
  </joint>
  <joint name="right_ankle_fixed" type="fixed">
    <origin rpy="0 0 0" xyz="-0.03 0 -0.05"/>
    <child link="right_foot"/>
    <parent link="right_ankle_y"/>
    <axis rpy="0 0 0" xyz="1 0 0"/>
  </joint>
  <link name="right_foot_s1">
    <inertial>
      <mass value="0.001"/>
      <origin rpy=" 0 0 0" xyz="0 0 0"/>
      <inertia ixx="0.4" ixy="0.0" ixz="0.0" iyy="0.4" iyz="0.0" izz="0.2"/>
    </inertial>
    <collision name="right_foot_s1_collision">
      <geometry>
        <box size="0.04 0.04 0.002"/>
      </geometry>
    </collision>
    <visual name="right_foot_s1_visual">
      <origin rpy=" 0 0 0" xyz="0 0 0"/>
      <geometry>
        <box size="0.04 0.04 0.002"/>
      </geometry>
    </visual>
  </link>
  <joint name="right_foot_s1_fixed" type="fixed">
    <origin rpy="0 0 0" xyz="0.105 0.04 -0.027"/>
    <child link="right_foot_s1"/>
    <parent link="right_foot"/>
    <axis rpy="0 0 0" xyz="1 0 0"/>
  </joint>
  <link name="right_foot_s2">
    <inertial>
      <mass value="0.001"/>
      <origin rpy=" 0 0 0" xyz="0 0 0"/>
      <inertia ixx="0.4" ixy="0.0" ixz="0.0" iyy="0.4" iyz="0.0" izz="0.2"/>
    </inertial>
    <collision name="right_foot_s2_collision">
      <geometry>
        <box size="0.04 0.04 0.002"/>
      </geometry>
    </collision>
    <visual name="right_foot_s2_visual">
      <origin rpy=" 0 0 0" xyz="0 0 0"/>
      <geometry>
        <box size="0.04 0.04 0.002"/>
      </geometry>
    </visual>
  </link>
  <joint name="right_foot_s2_fixed" type="fixed">
    <origin rpy="0 0 0" xyz="0.105 -0.04 -0.027"/>
    <child link="right_foot_s2"/>
    <parent link="right_foot"/>
    <axis rpy="0 0 0" xyz="1 0 0"/>
  </joint>
  <link name="right_foot_s3">
    <inertial>
      <mass value="0.001"/>
      <origin rpy=" 0 0 0" xyz="0 0 0"/>
      <inertia ixx="0.4" ixy="0.0" ixz="0.0" iyy="0.4" iyz="0.0" izz="0.2"/>
    </inertial>
    <collision name="right_foot_s3_collision">
      <geometry>
        s
      
        <box size="0.04 0.04 0.002"/>
      </geometry>
    </collision>
    <visual name="right_foot_s3_visual">
      <origin rpy=" 0 0 0" xyz="0 0 0"/>
      <geometry>
        <box size="0.04 0.04 0.002"/>
      </geometry>
    </visual>
  </link>
  <joint name="right_foot_s3_fixed" type="fixed">
    <origin rpy="0 0 0" xyz="-0.105 0.04 -0.027"/>
    <child link="right_foot_s3"/>
    <parent link="right_foot"/>
    <axis rpy="0 0 0" xyz="1 0 0"/>
  </joint>
  <link name="right_foot_s4">
    <inertial>
      <mass value="0.001"/>
      <origin rpy=" 0 0 0" xyz="0 0 0"/>
      <inertia ixx="0.4" ixy="0.0" ixz="0.0" iyy="0.4" iyz="0.0" izz="0.2"/>
    </inertial>
    <collision name="right_foot_s4_collision">
      <geometry>
        <box size="0.04 0.04 0.002"/>
      </geometry>
    </collision>
    <visual name="right_foot_s4_visual">
      <origin rpy=" 0 0 0" xyz="0 0 0"/>
      <geometry>
        <box size="0.04 0.04 0.002"/>
      </geometry>
    </visual>
  </link>
  <joint name="right_foot_s4_fixed" type="fixed">
    <origin rpy="0 0 0" xyz="-0.105 -0.04 -0.027"/>
    <child link="right_foot_s4"/>
    <parent link="right_foot"/>
    <axis rpy="0 0 0" xyz="1 0 0"/>
  </joint>
  <transmission name="tran_right_ankle_x">
    <type>transmission_interface/SimpleTransmission</type>
    <joint name="right_ankle_x_joint">
      <hardwareInterface>hardware_interface/EffortJointInterface</hardwareInterface>
    </joint>
    <actuator name="motor_right_ankle_x">
      <hardwareInterface>hardware_interface/EffortJointInterface</hardwareInterface>
      <mechanicalReduction>1</mechanicalReduction>
    </actuator>
  </transmission>
  <transmission name="tran_right_ankle_y">
    <type>transmission_interface/SimpleTransmission</type>
    <joint name="right_ankle_y_joint">
      <hardwareInterface>hardware_interface/EffortJointInterface</hardwareInterface>
    </joint>
    <actuator name="motor_right_ankle_y">
      <hardwareInterface>hardware_interface/EffortJointInterface</hardwareInterface>
      <mechanicalReduction>1</mechanicalReduction>
    </actuator>
  </transmission>
  <!--  SENSORS -->
  <link name="imu_link">
    <inertial>
      <mass value="0.01"/>
      <origin rpy=" 0 0 0" xyz="0 0 0"/>
      <inertia ixx="0.4" ixy="0.0" ixz="0.0" iyy="0.4" iyz="0.0" izz="0.2"/>
    </inertial>
    <visual>
      <origin rpy="0 0 0" xyz="0 0 0"/>
      <geometry>
        <box size="0.01 0.01 0.01"/>
      </geometry>
    </visual>
    <collision>
      <geometry>
        <box size="0.01 0.01 0.01"/>
      </geometry>
    </collision>
  </link>
  <joint name="imu_joint" type="fixed">
    <axis xyz="0 0 0"/>
    <origin rpy="0 0 0" xyz="0.0 0 0.01"/>
    <parent link="hips"/>
    <child link="imu_link"/>
  </joint>
  <gazebo>
    <plugin filename="libgazebo_ros_imu.so" name="imu_plugin">
      <alwaysOn>true</alwaysOn>
      <bodyName>imu_link</bodyName>
      <topicName>imu_data</topicName>
      <serviceName>imu_service</serviceName>
      <gaussianNoise>0.0</gaussianNoise>
      <updateRate>10.0</updateRate>
    </plugin>
  </gazebo>
  <link name="camera_link">
    <collision>
      <origin rpy="0 0 0" xyz="0 0 0"/>
      <geometry>
        <box size="0.05 0.05 0.05"/>
      </geometry>
    </collision>
    <visual>
      <origin rpy="0 0 0" xyz="0 0 0"/>
      <material name="green"/>
      <geometry>
        <box size="0.05 0.05 0.05"/>
      </geometry>
    </visual>
    <inertial>
      <mass value="1e-5"/>
      <origin rpy="0 0 0" xyz="0 0 0"/>
      <inertia ixx="0.4" ixy="0.0" ixz="0.0" iyy="0.4" iyz="0.0" izz="0.2"/>
    </inertial>
  </link>
  <joint name="camera_joint" type="fixed">
    <axis xyz="0 0 0"/>
    <origin rpy="0 0.785398163397 1.57079632679" xyz="0.09 0 0"/>
    <parent link="hips"/>
    <child link="camera_link"/>
  </joint>
  <link name="camera_link_optical">
    <inertial>
      <mass value="1e-5"/>
      <origin rpy="0 0 0" xyz="0 0 0"/>
      <inertia ixx="0.4" ixy="0.0" ixz="0.0" iyy="0.4" iyz="0.0" izz="0.2"/>
    </inertial>
  </link>
  <!-- generate an optical frame http://www.ros.org/reps/rep-0103.html#suffix-frames
      so that ros and opencv can operate on the camera frame correctly -->
  <!-- these values have to be these values otherwise the gazebo camera image
          won"t be aligned properly with the frame it is supposedly originating from -->
  <joint name="camera_optical_joint" type="fixed">
    <origin rpy="-1.57079632679 0 -1.57079632679" xyz="0 0 0"/>
    <parent link="camera_link"/>
    <child link="camera_link_optical"/>
  </joint>
</robot>

